<?xml version="1.0"?>
<robot name="myrobot">



    <link name="base_link">
        <visual>
            <geometry>
                <box size="0.6 0.3 0.3"/>
            </geometry>
            <material name="silver">
                <color rgba="0.75 0.75 0.75 1"/>
            </material>
        </visual>
        <collision>
            <geometry>
                <box size="0.6 0.3 0.3"/>
            </geometry>
        </collision>
        <inertial>
            <mass value="1.0"/> <!--1kg-->
            <inertia ixx="0.015" iyy="0.0375" izz="0.0375" ixy="0" ixz="0" iyz="0"/>
        </inertial>
    </link>




    <link name="front_caster">
        <visual>
            <geometry>
                <box size="0.1 0.1 0.3"/>
            </geometry>
            <material name="silver"/>
        </visual>
        <collision>
            <geometry>
                <box size="0.1 0.1 0.3"/>
            </geometry>
        </collision>
        <inertial>
            <mass value="0.1"/> <!--0.1kg-->
            <inertia ixx="0.00083" iyy="0.00083" izz="0.000167" ixy="0" ixz="0" iyz="0"/>
        </inertial>
    </link>

    <joint name="front_caster_joint" type="continuous">
        <axis xyz="0 0 1"/>
        <parent link="base_link"/>
        <child link="front_caster"/>
        <origin rpy="0 0 0" xyz="0.3 0 0"/>
    </joint>
    
    
    
    
    <link name="front_wheel">
        <visual>
            <geometry>
                <cylinder length="0.05" radius="0.035"/>
            </geometry>
            <material name="black">
                <color rgba="0 0 0 1"/>
            </material>
        </visual>
        <collision>
            <geometry>
                <cylinder length="0.05" radius="0.035"/>
            </geometry>
        </collision>
        <inertial>
            <mass value="0.1"/> <!--0.1kg-->
            <inertia ixx="5.148e-5" iyy="5.148e-5" izz="6.125e-5" ixy="0" ixz="0" iyz="0"/>
        </inertial>
    </link>
    
    <joint name="front_wheel_joint" type="continuous">
        <axis xyz="0 0 1"/>
        <parent link="front_caster"/>
        <child link="front_wheel"/>
        <origin rpy="-1.5708 0 0" xyz="0.05 0 -0.15"/>
    </joint>
    
    
    
    
    
    <link name="right_wheel">
        <visual>
            <geometry>
                <cylinder length="0.05" radius="0.035"/>
            </geometry>
            <material name="black">
                <color rgba="0 0 0 1"/>
            </material>
        </visual>
        <collision>
            <geometry>
                <cylinder length="0.05" radius="0.035"/>
            </geometry>
        </collision>
        <inertial>
            <mass value="0.1"/> <!--0.1kg-->
            <inertia ixx="5.148e-5" iyy="5.148e-5" izz="6.125e-5" ixy="0" ixz="0" iyz="0"/>
        </inertial>
    </link>
    
    <joint name="right_wheel_joint" type="continuous">
        <axis xyz="0 0 1"/>
        <parent link="base_link"/>
        <child link="right_wheel"/>
        <origin rpy="-1.5708 0 0" xyz="-0.2825 -0.125 -0.15"/>
    </joint>
    
    
    
    
    <link name="left_wheel">
        <visual>
            <geometry>
                <cylinder length="0.05" radius="0.035"/>
            </geometry>
            <material name="black">
                <color rgba="0 0 0 1"/>
            </material>
        </visual>
        <collision>
            <geometry>
                <cylinder length="0.05" radius="0.035"/>
            </geometry>
        </collision>
        <inertial>
            <mass value="0.1"/> <!--0.1kg-->
            <inertia ixx="5.148e-5" iyy="5.148e-5" izz="6.125e-5" ixy="0" ixz="0" iyz="0"/>
        </inertial>
    </link>
    
    <joint name="left_wheel_joint" type="continuous">
        <axis xyz="0 0 1"/>
        <parent link="base_link"/>
        <child link="left_wheel"/>
        <origin rpy="-1.5708 0 0" xyz="-0.2825 0.125 -0.15"/>
    </joint>  
    
    
    
    <link name="lidar_link">
        <visual>
            <origin xyz="0 0 0" rpy="0 0 0"/>
            <geometry>
                <box size="0.1 0.1 0.1"/>
            </geometry>
            <material name="black">
                <color rgba="0 0 0 1"/>
            </material>
        </visual>
        <collision>
            <origin xyz="0 0 0" rpy="0 0 0"/>
            <geometry>
                <box size="0.1 0.1 0.1"/>
            </geometry>
        </collision>
        <inertial>
            <mass value="1e-5"/> 
            <inertia ixx="1e-6" iyy="1e-6" izz="1e-6" ixy="0" ixz="0" iyz="0"/>
        </inertial>
    </link>
    
    <joint name="lidar_joint" type="fixed">
        <axis xyz="0 1 0"/>
        <parent link="base_link"/>
        <child link="lidar_link"/>
        <origin rpy="0 0 0" xyz="0 0 0.2"/>
    </joint>  
    
    
    
    
    
    <link name="camera_link">
        <visual>
            <origin xyz="0 0 0" rpy="0 0 0"/>
            <geometry>
                <box size="0.05 0.05 0.05"/>
            </geometry>
            <material name="black">
                <color rgba="0 0 0 1"/>
            </material>
        </visual>
        <collision>
            <origin xyz="0 0 0" rpy="0 0 0"/>
            <geometry>
                <box size="0.05 0.05 0.05"/>
            </geometry>
        </collision>
        <inertial>
            <mass value="2e-6"/> 
            <inertia ixx="1e-7" iyy="1e-7" izz="1e-7" ixy="0" ixz="0" iyz="0"/>
        </inertial>
    </link>
    
    <joint name="camera_joint" type="fixed">
        <axis xyz="0 1 0"/>
        <parent link="base_link"/>
        <child link="camera_link"/>
        <origin rpy="0 0 0" xyz="0.3 0 0.1"/>
    </joint>  
    
    
    
    
    <gazebo reference="lidar_link">
        <material>Gazebo/FlatBlack</material>
        <sensor type="ray" name="LIDAR">
            <pose>0 0 0 0 0 0</pose>
            <visualize>true</visualize>
            <update_rate>40</update_rate>
            <ray>
                <scan>
                    <horizontal>
                    <samples>360</samples>
                    <resolution>1</resolution>
                    <min_angle>-1.570796</min_angle>
                    <max_angle>1.570796</max_angle>
                  </horizontal>
                </scan>
            <range>
                <min>0.1</min>
                <max>3.5</max>
                <resolution>0.01</resolution>
            </range>
        </ray>
        <plugin name="lidar_controller" filename="libgazebo_ros_laser.so">
          <topicName>scan</topicName>
          <frameName>lidar_link</frameName>
        </plugin>
      </sensor>
    </gazebo>
    
    
    
    <gazebo reference="camera_link">
        <sensor type="camera" name="Camera">
            <always_on>true</always_on>
            <visualize>true</visualize>
            <camera>
                <horizontal_fov>1.085595</horizontal_fov>
                <image>
                    <width>640</width>
                    <height>480</height>
                    <format>R8G8B8</format>
                </image>
                <clip>
                    <near>0.03</near>
                    <far>100</far>
                </clip>
            </camera>
            <plugin name="camera_controller" filename="libgazebo_ros_camera.so">
                <alwaysOn>true</alwaysOn>
                <updateRate>30.0</updateRate>
                <cameraName>camera</cameraName>
                <frameName>camera_rgb_optical_frame</frameName>
                <imageTopicName>rgb/image_raw</imageTopicName>
                <cameraInfoTopicName>rgb/camera_info</cameraInfoTopicName>
                <hackBaseline>0.07</hackBaseline>
                <distortionK1>0.0</distortionK1>
                <distortionK2>0.0</distortionK2>
                <distortionK3>0.0</distortionK3>
                <distortionT1>0.0</distortionT1>
                <distortionT2>0.0</distortionT2>
            </plugin>
        </sensor>
    </gazebo>
    
    
    
    
    
    
    
    
    <gazebo>
        <plugin name="gazebo_controller_test" filename="libgazebo_ros_diff_drive.so">
            <commandTopic>cmd_vel</commandTopic>
            <odometryTopic>odom</odometryTopic>
            <odometryFrame>odom</odometryFrame>
            <odometrySource>world</odometrySource>
            <publishOdomTF>true</publishOdomTF>
            <publishTf>true</publishTf>
            <leftJoint>left_wheel_joint</leftJoint>
            <rightJoint>right_wheel_joint</rightJoint>
            <robotBaseFrame>base_link</robotBaseFrame> <!--로봇의 이동 기본체는 base_link-->
            <wheelSeparation>0.25</wheelSeparation> <!--바퀴 사이 거리-->
            <wheelDiameter>0.07</wheelDiameter>
            <publishWheelJointState>true</publishWheelJointState>
            <wheelTorque>10</wheelTorque>
        </plugin>
    </gazebo>
        
    

</robot>





